<sdf version='1.9'>
  <world name="car_world">

    <spherical_coordinates>
      <surface_model>EARTH_WGS84</surface_model>
      <world_frame_orientation>ENU</world_frame_orientation>
      <latitude_deg>47.397742</latitude_deg>    <!-- same as sensor -->
      <longitude_deg>8.545594</longitude_deg>
      <elevation>488.0</elevation>
      <heading_deg>0</heading_deg>
    </spherical_coordinates>
    
    <physics name="1ms" type="ignored">
      <max_step_size>0.001</max_step_size>
      <real_time_factor>1.0</real_time_factor>
    </physics>
    <plugin
      filename="libignition-gazebo-physics-system.so"
      name="ignition::gazebo::systems::Physics">
    </plugin>
    <plugin
      filename="libignition-gazebo-user-commands-system.so"
      name="ignition::gazebo::systems::UserCommands">
    </plugin>
    <plugin
      filename="libignition-gazebo-scene-broadcaster-system.so"
      name="ignition::gazebo::systems::SceneBroadcaster">
    </plugin>

    <light type="directional" name="sun">
      <cast_shadows>true</cast_shadows>
      <pose>0 0 10 0 0 0</pose>
      <diffuse>0.8 0.8 0.8 1</diffuse>
      <specular>0.2 0.2 0.2 1</specular>
      <attenuation>
        <range>1000</range>
        <constant>0.9</constant>
        <linear>0.01</linear>
        <quadratic>0.001</quadratic>
      </attenuation>
      <direction>-0.5 0.1 -0.9</direction>
    </light>

    <model name="ground_plane">
      <static>true</static>
      <link name="link">
        <collision name="collision">
          <geometry>
            <plane>
              <normal>0 0 1</normal>
            </plane>
          </geometry>
        </collision>
        <visual name="visual">
          <geometry>
            <plane>
              <normal>0 0 1</normal>
              <size>100 100</size>
            </plane>
          </geometry>
          <material>
            <ambient>0.8 0.8 0.8 1</ambient>
            <diffuse>0.8 0.8 0.8 1</diffuse>
            <specular>0.8 0.8 0.8 1</specular>
          </material>
        </visual>
      </link>
    </model>
    <model name='Assem1'>
      <pose>0 0 0.1 0 0 0</pose>
      <link name='base_link'>
        <inertial>
          <pose>-0.001613669887424211 0.04743360968844424 0.07810236372253125 0 0 0</pose>
          <mass>5.169215648886329</mass>
          <inertia>
            <ixx>0.26340802474638231</ixx>
            <ixy>-9.4946831182606245e-05</ixy>
            <ixz>0.00014214496635701069</ixz>
            <iyy>0.15252833197381879</iyy>
            <iyz>0.00037637662006314779</iyz>
            <izz>0.37115471987722631</izz>
          </inertia>
        </inertial>

        <sensor name="imu" type="imu">
          <always_on>1</always_on>
          <update_rate>100</update_rate>
          <topic>/imu</topic>
          <imu>
            <enable_orientation>0</enable_orientation>
            <angular_velocity>
              <x>
                <noise type="gaussian">
                  <mean>0</mean>
                  <stddev>0.009</stddev>
                  <bias_mean>0.00075</bias_mean>
                  <bias_stddev>0.005</bias_stddev>
                  <dynamic_bias_stddev>0.00002</dynamic_bias_stddev>
                  <dynamic_bias_correlation_time>400.0</dynamic_bias_correlation_time>
                  <precision>0.00025</precision>
                </noise>
              </x>
              <y>
                <noise type="gaussian">
                  <mean>0</mean>
                  <stddev>0.009</stddev>
                  <bias_mean>0.00075</bias_mean>
                  <bias_stddev>0.005</bias_stddev>
                  <dynamic_bias_stddev>0.00002</dynamic_bias_stddev>
                  <dynamic_bias_correlation_time>400.0</dynamic_bias_correlation_time>
                  <precision>0.00025</precision>
                </noise>
              </y>
              <z>
                <noise type="gaussian">
                  <mean>0</mean>
                  <stddev>0.009</stddev>
                  <bias_mean>0.00075</bias_mean>
                  <bias_stddev>0.005</bias_stddev>
                  <dynamic_bias_stddev>0.00002</dynamic_bias_stddev>
                  <dynamic_bias_correlation_time>400.0</dynamic_bias_correlation_time>
                  <precision>0.00025</precision>
                </noise>
              </z>
            </angular_velocity>
            <linear_acceleration>
              <x>
                <noise type="gaussian">
                  <mean>0</mean>
                  <stddev>0.021</stddev>
                  <bias_mean>0.05</bias_mean>
                  <bias_stddev>0.0075</bias_stddev>
                  <dynamic_bias_stddev>0.000375</dynamic_bias_stddev>
                  <dynamic_bias_correlation_time>175.0</dynamic_bias_correlation_time>
                  <precision>0.005</precision>
                </noise>
              </x>
              <y>
                <noise type="gaussian">
                  <mean>0</mean>
                  <stddev>0.021</stddev>
                  <bias_mean>0.05</bias_mean>
                  <bias_stddev>0.0075</bias_stddev>
                  <dynamic_bias_stddev>0.000375</dynamic_bias_stddev>
                  <dynamic_bias_correlation_time>175.0</dynamic_bias_correlation_time>
                  <precision>0.005</precision>
                </noise>
              </y>
              <z>
                <noise type="gaussian">
                  <mean>0</mean>
                  <stddev>0.021</stddev>
                  <bias_mean>0.05</bias_mean>
                  <bias_stddev>0.0075</bias_stddev>
                  <dynamic_bias_stddev>0.000375</dynamic_bias_stddev>
                  <dynamic_bias_correlation_time>175.0</dynamic_bias_correlation_time>
                  <precision>0.005</precision>
                </noise>
              </z>
            </linear_acceleration>
          </imu>
        </sensor>

        <collision name='base_link_collision'>
          <pose>0 0 0 0 0 0</pose>
          <geometry>
            <mesh>
              <scale>1 1 1</scale>
              <uri>./meshes/base_link.STL</uri>
            </mesh>
          </geometry>
        </collision>
        <collision name='base_link_fixed_joint_lump__LDR_Link_collision_1'>
          <pose>-0.00028089 -0.16448 0.19368 0 0 0</pose>
          <geometry>
            <mesh>
              <scale>1 1 1</scale>
              <uri>./meshes/LDR_Link.STL</uri>
            </mesh>
          </geometry>
        </collision>
        <collision name='base_link_fixed_joint_lump__Left_UltraSonic_Link_collision_2'>
          <pose>-0.19797 0.33668 0.14299 0 0 0</pose>
          <geometry>
            <mesh>
              <scale>1 1 1</scale>
              <uri>./meshes/Left_UltraSonic_Link.STL</uri>
            </mesh>
          </geometry>
        </collision>
        <collision name='base_link_fixed_joint_lump__Mid_UltraSonic_Link_collision_3'>
          <pose>-0.00028041 0.37868 0.062988 0 0 0</pose>
          <geometry>
            <mesh>
              <scale>1 1 1</scale>
              <uri>./meshes/Mid_UltraSonic_Link.STL</uri>
            </mesh>
          </geometry>
        </collision>
        <collision name='base_link_fixed_joint_lump__Rain_sensor_Link_collision_4'>
          <pose>-0.00016446 -0.21221 0.19478 0 0 0</pose>
          <geometry>
            <mesh>
              <scale>1 1 1</scale>
              <uri>./meshes/Rain_sensor_Link.STL</uri>
            </mesh>
          </geometry>
        </collision>
        <collision name='base_link_fixed_joint_lump__Right_UltraSonic_Link_collision_5'>
          <pose>0.19741 0.33668 0.14299 0 0 0</pose>
          <geometry>
            <mesh>
              <scale>1 1 1</scale>
              <uri>./meshes/Right_UltraSonic_Link.STL</uri>
            </mesh>
          </geometry>
        </collision>
        <visual name='base_link_visual'>
          <pose>0 0 0 0 0 0</pose>
          <geometry>
            <mesh>
              <scale>1 1 1</scale>
              <uri>./meshes/base_link.STL</uri>
            </mesh>
          </geometry>
          <material>
            <diffuse>0.25 0.25 0.25 1</diffuse>
            <ambient>0.25 0.25 0.25 1</ambient>
          </material>
        </visual>
        <visual name='base_link_fixed_joint_lump__LDR_Link_visual_1'>
          <pose>-0.00028089 -0.16448 0.19368 0 0 0</pose>
          <geometry>
            <mesh>
              <scale>1 1 1</scale>
              <uri>./meshes/LDR_Link.STL</uri>
            </mesh>
          </geometry>
          <material>
            <diffuse>1 0.921569 0.583333 1</diffuse>
            <ambient>1 0.921569 0.583333 1</ambient>
          </material>
        </visual>
        <visual name='base_link_fixed_joint_lump__Left_UltraSonic_Link_visual_2'>
          <pose>-0.19797 0.33668 0.14299 0 0 0</pose>
          <geometry>
            <mesh>
              <scale>1 1 1</scale>
              <uri>./meshes/Left_UltraSonic_Link.STL</uri>
            </mesh>
          </geometry>
          <material>
            <diffuse>0.25 0.25 0.25 1</diffuse>
            <ambient>0.25 0.25 0.25 1</ambient>
          </material>
        </visual>
        <visual name='base_link_fixed_joint_lump__Mid_UltraSonic_Link_visual_3'>
          <pose>-0.00028041 0.37868 0.062988 0 0 0</pose>
          <geometry>
            <mesh>
              <scale>1 1 1</scale>
              <uri>./meshes/Mid_UltraSonic_Link.STL</uri>
            </mesh>
          </geometry>
          <material>
            <diffuse>0.25 0.25 0.25 1</diffuse>
            <ambient>0.25 0.25 0.25 1</ambient>
          </material>
        </visual>
        <visual name='base_link_fixed_joint_lump__Rain_sensor_Link_visual_4'>
          <pose>-0.00016446 -0.21221 0.19478 0 0 0</pose>
          <geometry>
            <mesh>
              <scale>1 1 1</scale>
              <uri>./meshes/Rain_sensor_Link.STL</uri>
            </mesh>
          </geometry>
          <material>
            <diffuse>1 0.921569 0.583333 1</diffuse>
            <ambient>1 0.921569 0.583333 1</ambient>
          </material>
        </visual>
        <visual name='base_link_fixed_joint_lump__Right_UltraSonic_Link_visual_5'>
          <pose>0.19741 0.33668 0.14299 0 0 0</pose>
          <geometry>
            <mesh>
              <scale>1 1 1</scale>
              <uri>./meshes/Right_UltraSonic_Link.STL</uri>
            </mesh>
          </geometry>
          <material>
            <diffuse>0.25 0.25 0.25 1</diffuse>
            <ambient>0.25 0.25 0.25 1</ambient>
          </material>
        </visual>
      </link>
      <joint name='Back_Left_Wheel_Joint' type='revolute'>
        <pose relative_to='base_link'>-0.26628 -0.16812 -0.018196 0 0 0</pose>
        <parent>base_link</parent>
        <child>Back_Left_Wheel_Link</child>
        <axis>
          <xyz>1 0 0</xyz>
          <limit>
            <lower>-10000000000000000</lower>
            <upper>10000000000000000</upper>
          </limit>
          <dynamics>
            <spring_reference>0</spring_reference>
            <spring_stiffness>0</spring_stiffness>
          </dynamics>
        </axis>
      </joint>
      <link name='Back_Left_Wheel_Link'>
        <pose relative_to='Back_Left_Wheel_Joint'>0 0 0 0 0 0</pose>
        <inertial>
          <pose>0.0180002141847672 0 -1.11022302462516e-16 0 0 0</pose>
          <mass>5.74040111939052</mass>
          <inertia>
            <ixx>0.024701173916752101</ixx>
            <ixy>6.1785486823547901e-19</ixy>
            <ixz>-3.8344919595494203e-17</ixz>
            <iyy>0.012883168156823501</iyy>
            <iyz>8.4129297554754997e-20</iyz>
            <izz>0.012883168156823501</izz>
          </inertia>
        </inertial>
        <collision name='Back_Left_Wheel_Link_collision'>
          <pose>0 0 0 0 0 0</pose>
          <geometry>
            <mesh>
              <scale>1 1 1</scale>
              <uri>./meshes/Back_Left_Wheel_Link.STL</uri>
            </mesh>
          </geometry>
        </collision>
        <visual name='Back_Left_Wheel_Link_visual'>
          <pose>0 0 0 0 0 0</pose>
          <geometry>
            <mesh>
              <scale>1 1 1</scale>
              <uri>./meshes/Back_Left_Wheel_Link.STL</uri>
            </mesh>
          </geometry>
          <material>
            <diffuse>0.25 0.25 0.25 1</diffuse>
            <ambient>0.25 0.25 0.25 1</ambient>
          </material>
        </visual>
      </link>
      <joint name='Back_Right_Wheel_Joint' type='revolute'>
        <pose relative_to='base_link'>-0.26628 -0.16812 -0.018196 0 0 0</pose>
        <parent>base_link</parent>
        <child>Back_Right_Wheel_Link</child>
        <axis>
          <xyz>1 0 0</xyz>
          <limit>
            <lower>-10000000000000000</lower>
            <upper>10000000000000000</upper>
          </limit>
          <dynamics>
            <spring_reference>0</spring_reference>
            <spring_stiffness>0</spring_stiffness>
          </dynamics>
        </axis>
      </joint>
      <link name='Back_Right_Wheel_Link'>
        <pose relative_to='Back_Right_Wheel_Joint'>0 0 0 0 0 0</pose>
        <inertial>
          <pose>0.514000214184765 -5.52335954751015e-15 -4.44089209850063e-15 0 0 0</pose>
          <mass>5.7404011193905102</mass>
          <inertia>
            <ixx>0.024701173916752101</ixx>
            <ixy>2.65430082145206e-20</ixy>
            <ixz>1.34698732310558e-20</ixz>
            <iyy>0.0128831681568234</iyy>
            <iyz>-2.07715639723907e-20</iyz>
            <izz>0.0128831681568234</izz>
          </inertia>
        </inertial>
        <collision name='Back_Right_Wheel_Link_collision'>
          <pose>0 0 0 0 0 0</pose>
          <geometry>
            <mesh>
              <scale>1 1 1</scale>
              <uri>./meshes/Back_Right_Wheel_Link.STL</uri>
            </mesh>
          </geometry>
        </collision>
        <visual name='Back_Right_Wheel_Link_visual'>
          <pose>0 0 0 0 0 0</pose>
          <geometry>
            <mesh>
              <scale>1 1 1</scale>
              <uri>./meshes/Back_Right_Wheel_Link.STL</uri>
            </mesh>
          </geometry>
          <material>
            <diffuse>0.25 0.25 0.25 1</diffuse>
            <ambient>0.25 0.25 0.25 1</ambient>
          </material>
        </visual>
      </link>
      <joint name='Front_Left_Wheel_Joint' type='revolute'>
        <pose relative_to='base_link'>-0.26528 0.18418 -0.018196 0 0 0</pose>
        <parent>base_link</parent>
        <child>Front_Left_Wheel_Link</child>
        <axis>
          <xyz>1 0 0</xyz>
          <limit>
            <lower>-10000000000000000</lower>
            <upper>10000000000000000</upper>
          </limit>
          <dynamics>
            <spring_reference>0</spring_reference>
            <spring_stiffness>0</spring_stiffness>
          </dynamics>
        </axis>
      </joint>
      <link name='Front_Left_Wheel_Link'>
        <pose relative_to='Front_Left_Wheel_Joint'>0 0 0 0 0 0</pose>
        <inertial>
          <pose>0.0170002141847672 0 1.11022302462516e-16 0 0 0</pose>
          <mass>5.7404011193905102</mass>
          <inertia>
            <ixx>0.024701173916752101</ixx>
            <ixy>2.6382826966317798e-18</ixy>
            <ixz>4.1675703171269401e-17</ixz>
            <iyy>0.012883168156823501</iyy>
            <iyz>5.5681892476625799e-20</iyz>
            <izz>0.012883168156823501</izz>
          </inertia>
        </inertial>
        <collision name='Front_Left_Wheel_Link_collision'>
          <pose>0 0 0 0 0 0</pose>
          <geometry>
            <mesh>
              <scale>1 1 1</scale>
              <uri>./meshes/Front_Left_Wheel_Link.STL</uri>
            </mesh>
          </geometry>
        </collision>
        <visual name='Front_Left_Wheel_Link_visual'>
          <pose>0 0 0 0 0 0</pose>
          <geometry>
            <mesh>
              <scale>1 1 1</scale>
              <uri>./meshes/Front_Left_Wheel_Link.STL</uri>
            </mesh>
          </geometry>
          <material>
            <diffuse>0.25 0.25 0.25 1</diffuse>
            <ambient>0.25 0.25 0.25 1</ambient>
          </material>
        </visual>
      </link>
      <joint name='Front_Right_Wheel_Joint' type='revolute'>
        <pose relative_to='base_link'>0.26572 0.18418 -0.018176 0 0 0</pose>
        <parent>base_link</parent>
        <child>Front_Right_Wheel_Link</child>
        <axis>
          <xyz>1 0 0</xyz>
          <limit>
            <lower>-10000000000000000</lower>
            <upper>10000000000000000</upper>
          </limit>
          <dynamics>
            <spring_reference>0</spring_reference>
            <spring_stiffness>0</spring_stiffness>
          </dynamics>
        </axis>
      </joint>
      <link name='Front_Right_Wheel_Link'>
        <pose relative_to='Front_Right_Wheel_Joint'>0 0 0 0 0 0</pose>
        <inertial>
          <pose>-0.0179997858152329 0 0 0 0 0</pose>
          <mass>5.7404011193905102</mass>
          <inertia>
            <ixx>0.024701173916752101</ixx>
            <ixy>1.0780891540480801e-18</ixy>
            <ixz>-3.7852821250140798e-17</ixz>
            <iyy>0.0128831681568234</iyy>
            <iyz>-3.52568682324834e-18</iyz>
            <izz>0.0128831681568234</izz>
          </inertia>
        </inertial>

        <collision name='Front_Right_Wheel_Link_collision'>
          <pose>0 0 0 0 0 0</pose>
          <geometry>
            <mesh>
              <scale>1 1 1</scale>
              <uri>./meshes/Front_Right_Wheel_Link.STL</uri>
            </mesh>
          </geometry>
        </collision>
        <visual name='Front_Right_Wheel_Link_visual'>
          <pose>0 0 0 0 0 0</pose>
          <geometry>
            <mesh>
              <scale>1 1 1</scale>
              <uri>./meshes/Front_Right_Wheel_Link.STL</uri>
            </mesh>
          </geometry>
          <material>
            <diffuse>0.25 0.25 0.25 1</diffuse>
            <ambient>0.25 0.25 0.25 1</ambient>
          </material>
        </visual>
      </link>
      <frame name='LDR_Joint' attached_to='base_link'>
        <pose>-0.000281 -0.16448 0.19368 0 -0 0</pose>
      </frame>
      <frame name='LDR_Link' attached_to='LDR_Joint'/>
      <frame name='Left_UltraSonic_Joint' attached_to='base_link'>
        <pose>-0.19797 0.33668 0.14299 0 -0 0</pose>
      </frame>
      <frame name='Left_UltraSonic_Link' attached_to='Left_UltraSonic_Joint'/>
      <frame name='Mid_UltraSonic_Joint' attached_to='base_link'>
        <pose>-0.00028 0.37868 0.062988 0 -0 0</pose>
      </frame>
      <frame name='Mid_UltraSonic_Link' attached_to='Mid_UltraSonic_Joint'/>
      <frame name='Rain_sensor_Joint' attached_to='base_link'>
        <pose>-0.000164 -0.21221 0.19478 0 -0 0</pose>
      </frame>
      <frame name='Rain_sensor_Link' attached_to='Rain_sensor_Joint'/>
      <frame name='Right_UltraSonic_Joint' attached_to='base_link'>
        <pose>0.19741 0.33668 0.14299 0 -0 0</pose>
      </frame>
      <frame name='Right_UltraSonic_Link' attached_to='Right_UltraSonic_Joint'/>

      <plugin filename="libignition-gazebo-diff-drive-system.so" name="ignition::gazebo::systems::DiffDrive">
        <left_joint>Front_Left_Wheel_Joint</left_joint>
        <left_joint>Back_Left_Wheel_Joint</left_joint>
        <right_joint>Front_Right_Wheel_Joint</right_joint>
        <right_joint>Back_Right_Wheel_Joint</right_joint>
        <wheel_separation>0.53144</wheel_separation>
        <wheel_radius>0.1</wheel_radius>
        <odom_publish_frequency>50</odom_publish_frequency>
        <topic>cmd_vel</topic>
      </plugin>

      <plugin filename="gz-sim-joint-state-publisher-system"
              name="gz::sim::systems::JointStatePublisher">
        <joint_name>Front_Left_Wheel_Joint</joint_name>
        <joint_name>Front_Right_Wheel_Joint</joint_name>
        <joint_name>Back_Left_Wheel_Joint</joint_name>
        <joint_name>Back_Right_Wheel_Joint</joint_name>
            <update_rate>10</update_rate>

      </plugin>

        <plugin filename="ignition-gazebo-odometry-publisher-system"
                name="ignition::gazebo::systems::OdometryPublisher">
            <odom_frame>odom</odom_frame>
            <odom_covariance_topic>odom</odom_covariance_topic>
            <tf_topic>tf</tf_topic>
            <robot_base_frame>base_footprint</robot_base_frame>
            <!-- <odom_publish_frequency>100</odom_publish_frequency> -->
        </plugin>


        <plugin filename="ignition-gazebo-navsat-system" name="ignition::gazebo::systems::NavSat"/>
        <link name="gps_link">
          <sensor name="navsat_sensor" type="navsat">
            <always_on>1</always_on>
            <update_rate>1</update_rate>
            <topicName>/gps</topicName>
            <frameName>rtk_gps_link</frameName>
            <lat>47.397742</lat>
            <lon>8.545594</lon>
            <alt>488.0</alt>
          </sensor>
        </link>


    </model>
  </world>
</sdf>
